Workbook

Sheet 🏠 DASHBOARD
B2: 🏠 PRÁTICO DOCUMENTOS ONLINE — CALCULADORA DE EMOLUMENTOS
B4: 📋 DADOS DO IMÓVEL | H4: ⚙️ PARÂMETROS FINANCEIROS
B5: Valor do Imóvel (R$) | C5: 500000 | E5: ← Digite o valor aqui | H5: Taxa cobrada ao cliente | I5: 0.7 | K5: % da economia gerada
B6: UF do Estado do Imóvel | C6: SP | D6: =IFERROR(VLOOKUP(C6,_LISTAS!$A:$B,2,FALSE()),"— selecione") -> SP — São Paulo | H6: Comissão ao corretor | I6: 0.4 | K6: % do bruto PRÁTICO
H7: Alíquota de impostos | I7: 0.15 | K7: ISS + IRPJ estimado
B9: 🏛️ CARTÓRIOS PARCEIROS — CUSTO DA ESCRITURA (DINÂMICO)
B10: PARCEIRO | C10: ESTADO | D10: ESCRITURA | E10: ECONOMIA vs LOCAL | F10: STATUS | G10: OBSERVAÇÃO
B11: ● DF | C11: Distrito Federal | D11: =IFERROR(VLOOKUP($C$5,DF!$A:$C,3,TRUE()),0) -> 2372.2 | E11: =IFERROR(VLOOKUP($C$6,_RANK!$A:$E,5,FALSE())-D11,0) -> 4770.62 | F11: ✅ Parceiro Ativo | G11: Melhor acima de R$ 515.750
B12: ● RS | C12: Rio Grande do Sul | D12: =IFERROR(VLOOKUP($C$5,RS!$A:$C,3,TRUE()),0) -> 2473.7 | E12: =IFERROR(VLOOKUP($C$6,_RANK!$A:$E,5,FALSE())-D12,0) -> 4669.12 | F12: ✅ Parceiro Ativo | G12: Melhor até R$ 515.749
B13: ● SC | C13: Santa Catarina | D13: =IFERROR(VLOOKUP($C$5,SC!$A:$C,3,TRUE()),0) -> 2997.58 | E13: =IFERROR(VLOOKUP($C$6,_RANK!$A:$E,5,FALSE())-D13,0) -> 4145.24 | F13: 📊 Monitorar | G13: Intermediário
B15: =IF(D11=MIN(D11,D12,D13),"🔵 ENVIAR PARA DF — Distrito Federal é o mais econômico para este valor",IF(D12=MIN(D11,D12,D13),"🟢 ENVIAR PARA RS — Rio Grande do Sul é o mais econômico para este valor","⚪ VERIFICAR SC — Santa Catarina pode ser mais vantajoso")) -> 🔵 ENVIAR PARA DF — Distrito Federal é o mais econômico para este valor
B17: 📊 COMPARATIVO COM ESTADO LOCAL (todos os valores dinâmicos)
B18: ESTADO LOCAL | C18: ESCRITURA LOCAL | D18: + PROCURAÇÃO | E18: CUSTO TOTAL | F18: MELHOR PARCEIRO | G18: CUSTO PARCEIRO | H18: ECONOMIA TOTAL | I18: ECONOMIA % | J18: VIABILIDADE
B19: =C6&" — "&IFERROR(VLOOKUP(C6,_LISTAS!$A:$B,2,FALSE()),C6) -> SP — SP — São Paulo | C19: =IFERROR(VLOOKUP($C$5,INDIRECT(C6&"!$A:$C"),3,TRUE()),0) -> 6942.82 | D19: =IFERROR(VLOOKUP(C6,_LISTAS!$A:$D,4,FALSE()),200) -> 200 | E19: =IFERROR(D19+E19,0) -> 0 | F19: =IF(D11=MIN(D11,D12,D13),"DF",IF(D12=MIN(D11,D12,D13),"RS","SC")) -> DF | G19: =MIN(D11,D12,D13) -> 2372.2 | H19: =IFERROR(F19-H19,0) -> 0 | I19: =IFERROR(I19/F19,0) -> 0 | J19: =IF(I19>500,"✅ VIÁVEL","⚠️ Verificar") -> ⚠️ Verificar
B21: 💰 GANHOS DA PRÁTICO NESTA OPERAÇÃO
B22: BRUTO PRÁTICO | C22: REPASSE CORRETOR | D22: APÓS COMISSÃO | E22: APÓS IMPOSTOS | F22: LUCRO LÍQUIDO | G22: MARGEM %
B23: =IFERROR(I19*$I$5,0) -> 0 | C23: =IFERROR(B23*$I$6,0) -> 0 | D23: =IFERROR(B23-C23,0) -> 0 | E23: =IFERROR(D23*(1-$I$7),0) -> 0 | F23: =IFERROR(E23,0) -> 0 | G23: =IFERROR(F23/I19,0) -> 0
B25: 🎯 RANKING DINÂMICO — DO MAIS CARO AO MAIS BARATO (atualiza automaticamente com o valor digitado acima)
B26: Quanto mais caro o estado local, maior a economia que você oferece ao cliente. Valores recalculados automaticamente.
B27: # | C27: UF | D27: ESTADO | E27: ESCRITURA | F27: + PROC. | G27: CUSTO TOTAL | H27: PARCEIRO | I27: CUSTO PARC. | J27: ECONOMIA | K27: ECON. % | L27: BRUTO PRÁTICO | M27: POTENCIAL
B28: 1 | C28: =IFERROR(INDEX(_RANK!$A$2:$A$28,MATCH(LARGE(_RANK!$E$2:$E$28,1),_RANK!$E$2:$E$28,0)),"") -> AP | D28: =IFERROR(INDEX(_RANK!$B$2:$B$28,MATCH(LARGE(_RANK!$E$2:$E$28,1),_RANK!$E$2:$E$28,0)),"") -> Amapá | E28: =IFERROR(INDEX(_RANK!$C$2:$C$28,MATCH(LARGE(_RANK!$E$2:$E$28,1),_RANK!$E$2:$E$28,0)),0) -> 15030.42 | F28: =IFERROR(INDEX(_RANK!$D$2:$D$28,MATCH(LARGE(_RANK!$E$2:$E$28,1),_RANK!$E$2:$E$28,0)),0) -> 200 | G28: =LARGE(_RANK!$E$2:$E$28,1) -> 15230.42 | H28: =IFERROR(INDEX(_RANK!$F$2:$F$28,MATCH(LARGE(_RANK!$E$2:$E$28,1),_RANK!$E$2:$E$28,0)),"") -> RS | I28: =IFERROR(INDEX(_RANK!$G$2:$G$28,MATCH(LARGE(_RANK!$E$2:$E$28,1),_RANK!$E$2:$E$28,0)),0) -> 2473.7 | J28: =IFERROR(INDEX(_RANK!$H$2:$H$28,MATCH(LARGE(_RANK!$E$2:$E$28,1),_RANK!$E$2:$E$28,0)),0) -> 12756.72 | K28: =IFERROR(INDEX(_RANK!$I$2:$I$28,MATCH(LARGE(_RANK!$E$2:$E$28,1),_RANK!$E$2:$E$28,0)),0) -> 0.83758163 | L28: =IFERROR(INDEX(_RANK!$J$2:$J$28,MATCH(LARGE(_RANK!$E$2:$E$28,1),_RANK!$E$2:$E$28,0)),0) -> 8929.704 | M28: 🔴 ALTÍSSIMO
B29: 2 | C29: =IFERROR(INDEX(_RANK!$A$2:$A$28,MATCH(LARGE(_RANK!$E$2:$E$28,2),_RANK!$E$2:$E$28,0)),"") -> RN | D29: =IFERROR(INDEX(_RANK!$B$2:$B$28,MATCH(LARGE(_RANK!$E$2:$E$28,2),_RANK!$E$2:$E$28,0)),"") -> Rio Grande do Norte | E29: =IFERROR(INDEX(_RANK!$C$2:$C$28,MATCH(LARGE(_RANK!$E$2:$E$28,2),_RANK!$E$2:$E$28,0)),0) -> 14108.04 | F29: =IFERROR(INDEX(_RANK!$D$2:$D$28,MATCH(LARGE(_RANK!$E$2:$E$28,2),_RANK!$E$2:$E$28,0)),0) -> 200 | G29: =LARGE(_RANK!$E$2:$E$28,2) -> 14308.04 | H29: =IFERROR(INDEX(_RANK!$F$2:$F$28,MATCH(LARGE(_RANK!$E$2:$E$28,2),_RANK!$E$2:$E$28,0)),"") -> RS | I29: =IFERROR(INDEX(_RANK!$G$2:$G$28,MATCH(LARGE(_RANK!$E$2:$E$28,2),_RANK!$E$2:$E$28,0)),0) -> 2473.7 | J29: =IFERROR(INDEX(_RANK!$H$2:$H$28,MATCH(LARGE(_RANK!$E$2:$E$28,2),_RANK!$E$2:$E$28,0)),0) -> 11834.34 | K29: =IFERROR(INDEX(_RANK!$I$2:$I$28,MATCH(LARGE(_RANK!$E$2:$E$28,2),_RANK!$E$2:$E$28,0)),0) -> 0.82711119 | L29: =IFERROR(INDEX(_RANK!$J$2:$J$28,MATCH(LARGE(_RANK!$E$2:$E$28,2),_RANK!$E$2:$E$28,0)),0) -> 8284.038 | M29: 🔴 ALTÍSSIMO
B30: 3 | C30: =IFERROR(INDEX(_RANK!$A$2:$A$28,MATCH(LARGE(_RANK!$E$2:$E$28,3),_RANK!$E$2:$E$28,0)),"") -> AC | D30: =IFERROR(INDEX(_RANK!$B$2:$B$28,MATCH(LARGE(_RANK!$E$2:$E$28,3),_RANK!$E$2:$E$28,0)),"") -> Acre | E30: =IFERROR(INDEX(_RANK!$C$2:$C$28,MATCH(LARGE(_RANK!$E$2:$E$28,3),_RANK!$E$2:$E$28,0)),0) -> 13440.9 | F30: =IFERROR(INDEX(_RANK!$D$2:$D$28,MATCH(LARGE(_RANK!$E$2:$E$28,3),_RANK!$E$2:$E$28,0)),0) -> 150 | G30: =LARGE(_RANK!$E$2:$E$28,3) -> 13590.9 | H30: =IFERROR(INDEX(_RANK!$F$2:$F$28,MATCH(LARGE(_RANK!$E$2:$E$28,3),_RANK!$E$2:$E$28,0)),"") -> RS | I30: =IFERROR(INDEX(_RANK!$G$2:$G$28,MATCH(LARGE(_RANK!$E$2:$E$28,3),_RANK!$E$2:$E$28,0)),0) -> 2473.7 | J30: =IFERROR(INDEX(_RANK!$H$2:$H$28,MATCH(LARGE(_RANK!$E$2:$E$28,3),_RANK!$E$2:$E$28,0)),0) -> 11117.2 | K30: =IFERROR(INDEX(_RANK!$I$2:$I$28,MATCH(LARGE(_RANK!$E$2:$E$28,3),_RANK!$E$2:$E$28,0)),0) -> 0.81798851 | L30: =IFERROR(INDEX(_RANK!$J$2:$J$28,MATCH(LARGE(_RANK!$E$2:$E$28,3),_RANK!$E$2:$E$28,0)),0) -> 7782.04 | M30: 🔴 ALTÍSSIMO
B31: 4 | C31: =IFERROR(INDEX(_RANK!$A$2:$A$28,MATCH(LARGE(_RANK!$E$2:$E$28,4),_RANK!$E$2:$E$28,0)),"") -> AL | D31: =IFERROR(INDEX(_RANK!$B$2:$B$28,MATCH(LARGE(_RANK!$E$2:$E$28,4),_RANK!$E$2:$E$28,0)),"") -> Alagoas | E31: =IFERROR(INDEX(_RANK!$C$2:$C$28,MATCH(LARGE(_RANK!$E$2:$E$28,4),_RANK!$E$2:$E$28,0)),0) -> 11505.94 | F31: =IFERROR(INDEX(_RANK!$D$2:$D$28,MATCH(LARGE(_RANK!$E$2:$E$28,4),_RANK!$E$2:$E$28,0)),0) -> 22.43 | G31: =LARGE(_RANK!$E$2:$E$28,4) -> 11528.37 | H31: =IFERROR(INDEX(_RANK!$F$2:$F$28,MATCH(LARGE(_RANK!$E$2:$E$28,4),_RANK!$E$2:$E$28,0)),"") -> RS | I31: =IFERROR(INDEX(_RANK!$G$2:$G$28,MATCH(LARGE(_RANK!$E$2:$E$28,4),_RANK!$E$2:$E$28,0)),0) -> 2473.7 | J31: =IFERROR(INDEX(_RANK!$H$2:$H$28,MATCH(LARGE(_RANK!$E$2:$E$28,4),_RANK!$E$2:$E$28,0)),0) -> 9054.67 | K31: =IFERROR(INDEX(_RANK!$I$2:$I$28,MATCH(LARGE(_RANK!$E$2:$E$28,4),_RANK!$E$2:$E$28,0)),0) -> 0.785425 | L31: =IFERROR(INDEX(_RANK!$J$2:$J$28,MATCH(LARGE(_RANK!$E$2:$E$28,4),_RANK!$E$2:$E$28,0)),0) -> 6338.269 | M31: 🔴 ALTÍSSIMO
B32: 5 | C32: =IFERROR(INDEX(_RANK!$A$2:$A$28,MATCH(LARGE(_RANK!$E$2:$E$28,5),_RANK!$E$2:$E$28,0)),"") -> PB | D32: =IFERROR(INDEX(_RANK!$B$2:$B$28,MATCH(LARGE(_RANK!$E$2:$E$28,5),_RANK!$E$2:$E$28,0)),"") -> Paraíba | E32: =IFERROR(INDEX(_RANK!$C$2:$C$28,MATCH(LARGE(_RANK!$E$2:$E$28,5),_RANK!$E$2:$E$28,0)),0) -> 9369.12 | F32: =IFERROR(INDEX(_RANK!$D$2:$D$28,MATCH(LARGE(_RANK!$E$2:$E$28,5),_RANK!$E$2:$E$28,0)),0) -> 170.35 | G32: =LARGE(_RANK!$E$2:$E$28,5) -> 9539.47 | H32: =IFERROR(INDEX(_RANK!$F$2:$F$28,MATCH(LARGE(_RANK!$E$2:$E$28,5),_RANK!$E$2:$E$28,0)),"") -> RS | I32: =IFERROR(INDEX(_RANK!$G$2:$G$28,MATCH(LARGE(_RANK!$E$2:$E$28,5),_RANK!$E$2:$E$28,0)),0) -> 2473.7 | J32: =IFERROR(INDEX(_RANK!$H$2:$H$28,MATCH(LARGE(_RANK!$E$2:$E$28,5),_RANK!$E$2:$E$28,0)),0) -> 7065.77 | K32: =IFERROR(INDEX(_RANK!$I$2:$I$28,MATCH(LARGE(_RANK!$E$2:$E$28,5),_RANK!$E$2:$E$28,0)),0) -> 0.7406879 | L32: =IFERROR(INDEX(_RANK!$J$2:$J$28,MATCH(LARGE(_RANK!$E$2:$E$28,5),_RANK!$E$2:$E$28,0)),0) -> 4946.039 | M32: 🔴 ALTÍSSIMO
B33: 6 | C33: =IFERROR(INDEX(_RANK!$A$2:$A$28,MATCH(LARGE(_RANK!$E$2:$E$28,6),_RANK!$E$2:$E$28,0)),"") -> AM | D33: =IFERROR(INDEX(_RANK!$B$2:$B$28,MATCH(LARGE(_RANK!$E$2:$E$28,6),_RANK!$E$2:$E$28,0)),"") -> Amazonas | E33: =IFERROR(INDEX(_RANK!$C$2:$C$28,MATCH(LARGE(_RANK!$E$2:$E$28,6),_RANK!$E$2:$E$28,0)),0) -> 9021.69 | F33: =IFERROR(INDEX(_RANK!$D$2:$D$28,MATCH(LARGE(_RANK!$E$2:$E$28,6),_RANK!$E$2:$E$28,0)),0) -> 200 | G33: =LARGE(_RANK!$E$2:$E$28,6) -> 9221.69 | H33: =IFERROR(INDEX(_RANK!$F$2:$F$28,MATCH(LARGE(_RANK!$E$2:$E$28,6),_RANK!$E$2:$E$28,0)),"") -> RS | I33: =IFERROR(INDEX(_RANK!$G$2:$G$28,MATCH(LARGE(_RANK!$E$2:$E$28,6),_RANK!$E$2:$E$28,0)),0) -> 2473.7 | J33: =IFERROR(INDEX(_RANK!$H$2:$H$28,MATCH(LARGE(_RANK!$E$2:$E$28,6),_RANK!$E$2:$E$28,0)),0) -> 6747.99 | K33: =IFERROR(INDEX(_RANK!$I$2:$I$28,MATCH(LARGE(_RANK!$E$2:$E$28,6),_RANK!$E$2:$E$28,0)),0) -> 0.73175199 | L33: =IFERROR(INDEX(_RANK!$J$2:$J$28,MATCH(LARGE(_RANK!$E$2:$E$28,6),_RANK!$E$2:$E$28,0)),0) -> 4723.593 | M33: 🟠 ALTO
B34: 7 | C34: =IFERROR(INDEX(_RANK!$A$2:$A$28,MATCH(LARGE(_RANK!$E$2:$E$28,7),_RANK!$E$2:$E$28,0)),"") -> RO | D34: =IFERROR(INDEX(_RANK!$B$2:$B$28,MATCH(LARGE(_RANK!$E$2:$E$28,7),_RANK!$E$2:$E$28,0)),"") -> Rondônia | E34: =IFERROR(INDEX(_RANK!$C$2:$C$28,MATCH(LARGE(_RANK!$E$2:$E$28,7),_RANK!$E$2:$E$28,0)),0) -> 8711.83 | F34: =IFERROR(INDEX(_RANK!$D$2:$D$28,MATCH(LARGE(_RANK!$E$2:$E$28,7),_RANK!$E$2:$E$28,0)),0) -> 200 | G34: =LARGE(_RANK!$E$2:$E$28,7) -> 8911.83 | H34: =IFERROR(INDEX(_RANK!$F$2:$F$28,MATCH(LARGE(_RANK!$E$2:$E$28,7),_RANK!$E$2:$E$28,0)),"") -> RS | I34: =IFERROR(INDEX(_RANK!$G$2:$G$28,MATCH(LARGE(_RANK!$E$2:$E$28,7),_RANK!$E$2:$E$28,0)),0) -> 2473.7 | J34: =IFERROR(INDEX(_RANK!$H$2:$H$28,MATCH(LARGE(_RANK!$E$2:$E$28,7),_RANK!$E$2:$E$28,0)),0) -> 6438.13 | K34: =IFERROR(INDEX(_RANK!$I$2:$I$28,MATCH(LARGE(_RANK!$E$2:$E$28,7),_RANK!$E$2:$E$28,0)),0) -> 0.72242514 | L34: =IFERROR(INDEX(_RANK!$J$2:$J$28,MATCH(LARGE(_RANK!$E$2:$E$28,7),_RANK!$E$2:$E$28,0)),0) -> 4506.691 | M34: 🟠 ALTO
B35: 8 | C35: =IFERROR(INDEX(_RANK!$A$2:$A$28,MATCH(LARGE(_RANK!$E$2:$E$28,8),_RANK!$E$2:$E$28,0)),"") -> MA | D35: =IFERROR(INDEX(_RANK!$B$2:$B$28,MATCH(LARGE(_RANK!$E$2:$E$28,8),_RANK!$E$2:$E$28,0)),"") -> Maranhão | E35: =IFERROR(INDEX(_RANK!$C$2:$C$28,MATCH(LARGE(_RANK!$E$2:$E$28,8),_RANK!$E$2:$E$28,0)),0) -> 8388.96 | F35: =IFERROR(INDEX(_RANK!$D$2:$D$28,MATCH(LARGE(_RANK!$E$2:$E$28,8),_RANK!$E$2:$E$28,0)),0) -> 200 | G35: =LARGE(_RANK!$E$2:$E$28,8) -> 8588.96 | H35: =IFERROR(INDEX(_RANK!$F$2:$F$28,MATCH(LARGE(_RANK!$E$2:$E$28,8),_RANK!$E$2:$E$28,0)),"") -> RS | I35: =IFERROR(INDEX(_RANK!$G$2:$G$28,MATCH(LARGE(_RANK!$E$2:$E$28,8),_RANK!$E$2:$E$28,0)),0) -> 2473.7 | J35: =IFERROR(INDEX(_RANK!$H$2:$H$28,MATCH(LARGE(_RANK!$E$2:$E$28,8),_RANK!$E$2:$E$28,0)),0) -> 6115.26 | K35: =IFERROR(INDEX(_RANK!$I$2:$I$28,MATCH(LARGE(_RANK!$E$2:$E$28,8),_RANK!$E$2:$E$28,0)),0) -> 0.71199074 | L35: =IFERROR(INDEX(_RANK!$J$2:$J$28,MATCH(LARGE(_RANK!$E$2:$E$28,8),_RANK!$E$2:$E$28,0)),0) -> 4280.682 | M35: 🟠 ALTO
B36: 9 | C36: =IFERROR(INDEX(_RANK!$A$2:$A$28,MATCH(LARGE(_RANK!$E$2:$E$28,9),_RANK!$E$2:$E$28,0)),"") -> MS | D36: =IFERROR(INDEX(_RANK!$B$2:$B$28,MATCH(LARGE(_RANK!$E$2:$E$28,9),_RANK!$E$2:$E$28,0)),"") -> Mato Grosso do Sul | E36: =IFERROR(INDEX(_RANK!$C$2:$C$28,MATCH(LARGE(_RANK!$E$2:$E$28,9),_RANK!$E$2:$E$28,0)),0) -> 8219.16 | F36: =IFERROR(INDEX(_RANK!$D$2:$D$28,MATCH(LARGE(_RANK!$E$2:$E$28,9),_RANK!$E$2:$E$28,0)),0) -> 200 | G36: =LARGE(_RANK!$E$2:$E$28,9) -> 8419.16 | H36: =IFERROR(INDEX(_RANK!$F$2:$F$28,MATCH(LARGE(_RANK!$E$2:$E$28,9),_RANK!$E$2:$E$28,0)),"") -> RS | I36: =IFERROR(INDEX(_RANK!$G$2:$G$28,MATCH(LARGE(_RANK!$E$2:$E$28,9),_RANK!$E$2:$E$28,0)),0) -> 2473.7 | J36: =IFERROR(INDEX(_RANK!$H$2:$H$28,MATCH(LARGE(_RANK!$E$2:$E$28,9),_RANK!$E$2:$E$28,0)),0) -> 5945.46 | K36: =IFERROR(INDEX(_RANK!$I$2:$I$28,MATCH(LARGE(_RANK!$E$2:$E$28,9),_RANK!$E$2:$E$28,0)),0) -> 0.70618209 | L36: =IFERROR(INDEX(_RANK!$J$2:$J$28,MATCH(LARGE(_RANK!$E$2:$E$28,9),_RANK!$E$2:$E$28,0)),0) -> 4161.822 | M36: 🟠 ALTO
B37: 10 | C37: =IFERROR(INDEX(_RANK!$A$2:$A$28,MATCH(LARGE(_RANK!$E$2:$E$28,10),_RANK!$E$2:$E$28,0)),"") -> GO | D37: =IFERROR(INDEX(_RANK!$B$2:$B$28,MATCH(LARGE(_RANK!$E$2:$E$28,10),_RANK!$E$2:$E$28,0)),"") -> Goiás | E37: =IFERROR(INDEX(_RANK!$C$2:$C$28,MATCH(LARGE(_RANK!$E$2:$E$28,10),_RANK!$E$2:$E$28,0)),0) -> 7388.58 | F37: =IFERROR(INDEX(_RANK!$D$2:$D$28,MATCH(LARGE(_RANK!$E$2:$E$28,10),_RANK!$E$2:$E$28,0)),0) -> 200 | G37: =LARGE(_RANK!$E$2:$E$28,10) -> 7588.58 | H37: =IFERROR(INDEX(_RANK!$F$2:$F$28,MATCH(LARGE(_RANK!$E$2:$E$28,10),_RANK!$E$2:$E$28,0)),"") -> RS | I37: =IFERROR(INDEX(_RANK!$G$2:$G$28,MATCH(LARGE(_RANK!$E$2:$E$28,10),_RANK!$E$2:$E$28,0)),0) -> 2473.7 | J37: =IFERROR(INDEX(_RANK!$H$2:$H$28,MATCH(LARGE(_RANK!$E$2:$E$28,10),_RANK!$E$2:$E$28,0)),0) -> 5114.88 | K37: =IFERROR(INDEX(_RANK!$I$2:$I$28,MATCH(LARGE(_RANK!$E$2:$E$28,10),_RANK!$E$2:$E$28,0)),0) -> 0.67402334 | L37: =IFERROR(INDEX(_RANK!$J$2:$J$28,MATCH(LARGE(_RANK!$E$2:$E$28,10),_RANK!$E$2:$E$28,0)),0) -> 3580.416 | M37: 🟠 ALTO
B38: 11 | C38: =IFERROR(INDEX(_RANK!$A$2:$A$28,MATCH(LARGE(_RANK!$E$2:$E$28,11),_RANK!$E$2:$E$28,0)),"") -> ES | D38: =IFERROR(INDEX(_RANK!$B$2:$B$28,MATCH(LARGE(_RANK!$E$2:$E$28,11),_RANK!$E$2:$E$28,0)),"") -> Espírito Santo | E38: =IFERROR(INDEX(_RANK!$C$2:$C$28,MATCH(LARGE(_RANK!$E$2:$E$28,11),_RANK!$E$2:$E$28,0)),0) -> 7254.52 | F38: =IFERROR(INDEX(_RANK!$D$2:$D$28,MATCH(LARGE(_RANK!$E$2:$E$28,11),_RANK!$E$2:$E$28,0)),0) -> 180 | G38: =LARGE(_RANK!$E$2:$E$28,11) -> 7434.52 | H38: =IFERROR(INDEX(_RANK!$F$2:$F$28,MATCH(LARGE(_RANK!$E$2:$E$28,11),_RANK!$E$2:$E$28,0)),"") -> RS | I38: =IFERROR(INDEX(_RANK!$G$2:$G$28,MATCH(LARGE(_RANK!$E$2:$E$28,11),_RANK!$E$2:$E$28,0)),0) -> 2473.7 | J38: =IFERROR(INDEX(_RANK!$H$2:$H$28,MATCH(LARGE(_RANK!$E$2:$E$28,11),_RANK!$E$2:$E$28,0)),0) -> 4960.82 | K38: =IFERROR(INDEX(_RANK!$I$2:$I$28,MATCH(LARGE(_RANK!$E$2:$E$28,11),_RANK!$E$2:$E$28,0)),0) -> 0.66726836 | L38: =IFERROR(INDEX(_RANK!$J$2:$J$28,MATCH(LARGE(_RANK!$E$2:$E$28,11),_RANK!$E$2:$E$28,0)),0) -> 3472.574 | M38: 🟡 MÉDIO
B39: 12 | C39: =IFERROR(INDEX(_RANK!$A$2:$A$28,MATCH(LARGE(_RANK!$E$2:$E$28,12),_RANK!$E$2:$E$28,0)),"") -> PE | D39: =IFERROR(INDEX(_RANK!$B$2:$B$28,MATCH(LARGE(_RANK!$E$2:$E$28,12),_RANK!$E$2:$E$28,0)),"") -> Pernambuco | E39: =IFERROR(INDEX(_RANK!$C$2:$C$28,MATCH(LARGE(_RANK!$E$2:$E$28,12),_RANK!$E$2:$E$28,0)),0) -> 7084.1 | F39: =IFERROR(INDEX(_RANK!$D$2:$D$28,MATCH(LARGE(_RANK!$E$2:$E$28,12),_RANK!$E$2:$E$28,0)),0) -> 237.84 | G39: =LARGE(_RANK!$E$2:$E$28,12) -> 7321.94 | H39: =IFERROR(INDEX(_RANK!$F$2:$F$28,MATCH(LARGE(_RANK!$E$2:$E$28,12),_RANK!$E$2:$E$28,0)),"") -> RS | I39: =IFERROR(INDEX(_RANK!$G$2:$G$28,MATCH(LARGE(_RANK!$E$2:$E$28,12),_RANK!$E$2:$E$28,0)),0) -> 2473.7 | J39: =IFERROR(INDEX(_RANK!$H$2:$H$28,MATCH(LARGE(_RANK!$E$2:$E$28,12),_RANK!$E$2:$E$28,0)),0) -> 4848.24 | K39: =IFERROR(INDEX(_RANK!$I$2:$I$28,MATCH(LARGE(_RANK!$E$2:$E$28,12),_RANK!$E$2:$E$28,0)),0) -> 0.66215238 | L39: =IFERROR(INDEX(_RANK!$J$2:$J$28,MATCH(LARGE(_RANK!$E$2:$E$28,12),_RANK!$E$2:$E$28,0)),0) -> 3393.768 | M39: 🟡 MÉDIO
B40: 13 | C40: =IFERROR(INDEX(_RANK!$A$2:$A$28,MATCH(LARGE(_RANK!$E$2:$E$28,13),_RANK!$E$2:$E$28,0)),"") -> MT | D40: =IFERROR(INDEX(_RANK!$B$2:$B$28,MATCH(LARGE(_RANK!$E$2:$E$28,13),_RANK!$E$2:$E$28,0)),"") -> Mato Grosso | E40: =IFERROR(INDEX(_RANK!$C$2:$C$28,MATCH(LARGE(_RANK!$E$2:$E$28,13),_RANK!$E$2:$E$28,0)),0) -> 6948.45 | F40: =IFERROR(INDEX(_RANK!$D$2:$D$28,MATCH(LARGE(_RANK!$E$2:$E$28,13),_RANK!$E$2:$E$28,0)),0) -> 300 | G40: =LARGE(_RANK!$E$2:$E$28,13) -> 7248.45 | H40: =IFERROR(INDEX(_RANK!$F$2:$F$28,MATCH(LARGE(_RANK!$E$2:$E$28,13),_RANK!$E$2:$E$28,0)),"") -> RS | I40: =IFERROR(INDEX(_RANK!$G$2:$G$28,MATCH(LARGE(_RANK!$E$2:$E$28,13),_RANK!$E$2:$E$28,0)),0) -> 2473.7 | J40: =IFERROR(INDEX(_RANK!$H$2:$H$28,MATCH(LARGE(_RANK!$E$2:$E$28,13),_RANK!$E$2:$E$28,0)),0) -> 4774.75 | K40: =IFERROR(INDEX(_RANK!$I$2:$I$28,MATCH(LARGE(_RANK!$E$2:$E$28,13),_RANK!$E$2:$E$28,0)),0) -> 0.65872704 | L40: =IFERROR(INDEX(_RANK!$J$2:$J$28,MATCH(LARGE(_RANK!$E$2:$E$28,13),_RANK!$E$2:$E$28,0)),0) -> 3342.325 | M40: 🟡 MÉDIO
B41: 14 | C41: =IFERROR(INDEX(_RANK!$A$2:$A$28,MATCH(LARGE(_RANK!$E$2:$E$28,14),_RANK!$E$2:$E$28,0)),"") -> SP | D41: =IFERROR(INDEX(_RANK!$B$2:$B$28,MATCH(LARGE(_RANK!$E$2:$E$28,14),_RANK!$E$2:$E$28,0)),"") -> São Paulo | E41: =IFERROR(INDEX(_RANK!$C$2:$C$28,MATCH(LARGE(_RANK!$E$2:$E$28,14),_RANK!$E$2:$E$28,0)),0) -> 6942.82 | F41: =IFERROR(INDEX(_RANK!$D$2:$D$28,MATCH(LARGE(_RANK!$E$2:$E$28,14),_RANK!$E$2:$E$28,0)),0) -> 200 | G41: =LARGE(_RANK!$E$2:$E$28,14) -> 7142.82 | H41: =IFERROR(INDEX(_RANK!$F$2:$F$28,MATCH(LARGE(_RANK!$E$2:$E$28,14),_RANK!$E$2:$E$28,0)),"") -> RS | I41: =IFERROR(INDEX(_RANK!$G$2:$G$28,MATCH(LARGE(_RANK!$E$2:$E$28,14),_RANK!$E$2:$E$28,0)),0) -> 2473.7 | J41: =IFERROR(INDEX(_RANK!$H$2:$H$28,MATCH(LARGE(_RANK!$E$2:$E$28,14),_RANK!$E$2:$E$28,0)),0) -> 4669.12 | K41: =IFERROR(INDEX(_RANK!$I$2:$I$28,MATCH(LARGE(_RANK!$E$2:$E$28,14),_RANK!$E$2:$E$28,0)),0) -> 0.6536802 | L41: =IFERROR(INDEX(_RANK!$J$2:$J$28,MATCH(LARGE(_RANK!$E$2:$E$28,14),_RANK!$E$2:$E$28,0)),0) -> 3268.384 | M41: 🟡 MÉDIO
B42: 15 | C42: =IFERROR(INDEX(_RANK!$A$2:$A$28,MATCH(LARGE(_RANK!$E$2:$E$28,15),_RANK!$E$2:$E$28,0)),"") -> PI | D42: =IFERROR(INDEX(_RANK!$B$2:$B$28,MATCH(LARGE(_RANK!$E$2:$E$28,15),_RANK!$E$2:$E$28,0)),"") -> Piauí | E42: =IFERROR(INDEX(_RANK!$C$2:$C$28,MATCH(LARGE(_RANK!$E$2:$E$28,15),_RANK!$E$2:$E$28,0)),0) -> 6360.31 | F42: =IFERROR(INDEX(_RANK!$D$2:$D$28,MATCH(LARGE(_RANK!$E$2:$E$28,15),_RANK!$E$2:$E$28,0)),0) -> 200 | G42: =LARGE(_RANK!$E$2:$E$28,15) -> 6560.31 | H42: =IFERROR(INDEX(_RANK!$F$2:$F$28,MATCH(LARGE(_RANK!$E$2:$E$28,15),_RANK!$E$2:$E$28,0)),"") -> RS | I42: =IFERROR(INDEX(_RANK!$G$2:$G$28,MATCH(LARGE(_RANK!$E$2:$E$28,15),_RANK!$E$2:$E$28,0)),0) -> 2473.7 | J42: =IFERROR(INDEX(_RANK!$H$2:$H$28,MATCH(LARGE(_RANK!$E$2:$E$28,15),_RANK!$E$2:$E$28,0)),0) -> 4086.61 | K42: =IFERROR(INDEX(_RANK!$I$2:$I$28,MATCH(LARGE(_RANK!$E$2:$E$28,15),_RANK!$E$2:$E$28,0)),0) -> 0.6229294 | L42: =IFERROR(INDEX(_RANK!$J$2:$J$28,MATCH(LARGE(_RANK!$E$2:$E$28,15),_RANK!$E$2:$E$28,0)),0) -> 2860.627 | M42: 🟡 MÉDIO
B43: 16 | C43: =IFERROR(INDEX(_RANK!$A$2:$A$28,MATCH(LARGE(_RANK!$E$2:$E$28,16),_RANK!$E$2:$E$28,0)),"") -> MG | D43: =IFERROR(INDEX(_RANK!$B$2:$B$28,MATCH(LARGE(_RANK!$E$2:$E$28,16),_RANK!$E$2:$E$28,0)),"") -> Minas Gerais | E43: =IFERROR(INDEX(_RANK!$C$2:$C$28,MATCH(LARGE(_RANK!$E$2:$E$28,16),_RANK!$E$2:$E$28,0)),0) -> 5523.14 | F43: =IFERROR(INDEX(_RANK!$D$2:$D$28,MATCH(LARGE(_RANK!$E$2:$E$28,16),_RANK!$E$2:$E$28,0)),0) -> 68.94 | G43: =LARGE(_RANK!$E$2:$E$28,16) -> 5592.08 | H43: =IFERROR(INDEX(_RANK!$F$2:$F$28,MATCH(LARGE(_RANK!$E$2:$E$28,16),_RANK!$E$2:$E$28,0)),"") -> RS | I43: =IFERROR(INDEX(_RANK!$G$2:$G$28,MATCH(LARGE(_RANK!$E$2:$E$28,16),_RANK!$E$2:$E$28,0)),0) -> 2473.7 | J43: =IFERROR(INDEX(_RANK!$H$2:$H$28,MATCH(LARGE(_RANK!$E$2:$E$28,16),_RANK!$E$2:$E$28,0)),0) -> 3118.38 | K43: =IFERROR(INDEX(_RANK!$I$2:$I$28,MATCH(LARGE(_RANK!$E$2:$E$28,16),_RANK!$E$2:$E$28,0)),0) -> 0.55764224 | L43: =IFERROR(INDEX(_RANK!$J$2:$J$28,MATCH(LARGE(_RANK!$E$2:$E$28,16),_RANK!$E$2:$E$28,0)),0) -> 2182.866 | M43: 🟢 BAIXO
B44: 17 | C44: =IFERROR(INDEX(_RANK!$A$2:$A$28,MATCH(LARGE(_RANK!$E$2:$E$28,17),_RANK!$E$2:$E$28,0)),"") -> SE | D44: =IFERROR(INDEX(_RANK!$B$2:$B$28,MATCH(LARGE(_RANK!$E$2:$E$28,17),_RANK!$E$2:$E$28,0)),"") -> Sergipe | E44: =IFERROR(INDEX(_RANK!$C$2:$C$28,MATCH(LARGE(_RANK!$E$2:$E$28,17),_RANK!$E$2:$E$28,0)),0) -> 5179.16 | F44: =IFERROR(INDEX(_RANK!$D$2:$D$28,MATCH(LARGE(_RANK!$E$2:$E$28,17),_RANK!$E$2:$E$28,0)),0) -> 200 | G44: =LARGE(_RANK!$E$2:$E$28,17) -> 5379.16 | H44: =IFERROR(INDEX(_RANK!$F$2:$F$28,MATCH(LARGE(_RANK!$E$2:$E$28,17),_RANK!$E$2:$E$28,0)),"") -> RS | I44: =IFERROR(INDEX(_RANK!$G$2:$G$28,MATCH(LARGE(_RANK!$E$2:$E$28,17),_RANK!$E$2:$E$28,0)),0) -> 2473.7 | J44: =IFERROR(INDEX(_RANK!$H$2:$H$28,MATCH(LARGE(_RANK!$E$2:$E$28,17),_RANK!$E$2:$E$28,0)),0) -> 2905.46 | K44: =IFERROR(INDEX(_RANK!$I$2:$I$28,MATCH(LARGE(_RANK!$E$2:$E$28,17),_RANK!$E$2:$E$28,0)),0) -> 0.54013266 | L44: =IFERROR(INDEX(_RANK!$J$2:$J$28,MATCH(LARGE(_RANK!$E$2:$E$28,17),_RANK!$E$2:$E$28,0)),0) -> 2033.822 | M44: 🟢 BAIXO
B45: 18 | C45: =IFERROR(INDEX(_RANK!$A$2:$A$28,MATCH(LARGE(_RANK!$E$2:$E$28,18),_RANK!$E$2:$E$28,0)),"") -> TO | D45: =IFERROR(INDEX(_RANK!$B$2:$B$28,MATCH(LARGE(_RANK!$E$2:$E$28,18),_RANK!$E$2:$E$28,0)),"") -> Tocantins | E45: =IFERROR(INDEX(_RANK!$C$2:$C$28,MATCH(LARGE(_RANK!$E$2:$E$28,18),_RANK!$E$2:$E$28,0)),0) -> 5075.36 | F45: =IFERROR(INDEX(_RANK!$D$2:$D$28,MATCH(LARGE(_RANK!$E$2:$E$28,18),_RANK!$E$2:$E$28,0)),0) -> 200 | G45: =LARGE(_RANK!$E$2:$E$28,18) -> 5275.36 | H45: =IFERROR(INDEX(_RANK!$F$2:$F$28,MATCH(LARGE(_RANK!$E$2:$E$28,18),_RANK!$E$2:$E$28,0)),"") -> RS | I45: =IFERROR(INDEX(_RANK!$G$2:$G$28,MATCH(LARGE(_RANK!$E$2:$E$28,18),_RANK!$E$2:$E$28,0)),0) -> 2473.7 | J45: =IFERROR(INDEX(_RANK!$H$2:$H$28,MATCH(LARGE(_RANK!$E$2:$E$28,18),_RANK!$E$2:$E$28,0)),0) -> 2801.66 | K45: =IFERROR(INDEX(_RANK!$I$2:$I$28,MATCH(LARGE(_RANK!$E$2:$E$28,18),_RANK!$E$2:$E$28,0)),0) -> 0.53108413 | L45: =IFERROR(INDEX(_RANK!$J$2:$J$28,MATCH(LARGE(_RANK!$E$2:$E$28,18),_RANK!$E$2:$E$28,0)),0) -> 1961.162 | M45: 🟢 BAIXO
B46: 19 | C46: =IFERROR(INDEX(_RANK!$A$2:$A$28,MATCH(LARGE(_RANK!$E$2:$E$28,19),_RANK!$E$2:$E$28,0)),"") -> PR | D46: =IFERROR(INDEX(_RANK!$B$2:$B$28,MATCH(LARGE(_RANK!$E$2:$E$28,19),_RANK!$E$2:$E$28,0)),"") -> Paraná | E46: =IFERROR(INDEX(_RANK!$C$2:$C$28,MATCH(LARGE(_RANK!$E$2:$E$28,19),_RANK!$E$2:$E$28,0)),0) -> 4460.8 | F46: =IFERROR(INDEX(_RANK!$D$2:$D$28,MATCH(LARGE(_RANK!$E$2:$E$28,19),_RANK!$E$2:$E$28,0)),0) -> 200 | G46: =LARGE(_RANK!$E$2:$E$28,19) -> 4660.8 | H46: =IFERROR(INDEX(_RANK!$F$2:$F$28,MATCH(LARGE(_RANK!$E$2:$E$28,19),_RANK!$E$2:$E$28,0)),"") -> RS | I46: =IFERROR(INDEX(_RANK!$G$2:$G$28,MATCH(LARGE(_RANK!$E$2:$E$28,19),_RANK!$E$2:$E$28,0)),0) -> 2473.7 | J46: =IFERROR(INDEX(_RANK!$H$2:$H$28,MATCH(LARGE(_RANK!$E$2:$E$28,19),_RANK!$E$2:$E$28,0)),0) -> 2187.1 | K46: =IFERROR(INDEX(_RANK!$I$2:$I$28,MATCH(LARGE(_RANK!$E$2:$E$28,19),_RANK!$E$2:$E$28,0)),0) -> 0.46925421 | L46: =IFERROR(INDEX(_RANK!$J$2:$J$28,MATCH(LARGE(_RANK!$E$2:$E$28,19),_RANK!$E$2:$E$28,0)),0) -> 1530.97 | M46: 🟢 BAIXO
B47: 20 | C47: =IFERROR(INDEX(_RANK!$A$2:$A$28,MATCH(LARGE(_RANK!$E$2:$E$28,20),_RANK!$E$2:$E$28,0)),"") -> RR | D47: =IFERROR(INDEX(_RANK!$B$2:$B$28,MATCH(LARGE(_RANK!$E$2:$E$28,20),_RANK!$E$2:$E$28,0)),"") -> Roraima | E47: =IFERROR(INDEX(_RANK!$C$2:$C$28,MATCH(LARGE(_RANK!$E$2:$E$28,20),_RANK!$E$2:$E$28,0)),0) -> 4213.03 | F47: =IFERROR(INDEX(_RANK!$D$2:$D$28,MATCH(LARGE(_RANK!$E$2:$E$28,20),_RANK!$E$2:$E$28,0)),0) -> 200 | G47: =LARGE(_RANK!$E$2:$E$28,20) -> 4413.03 | H47: =IFERROR(INDEX(_RANK!$F$2:$F$28,MATCH(LARGE(_RANK!$E$2:$E$28,20),_RANK!$E$2:$E$28,0)),"") -> RS | I47: =IFERROR(INDEX(_RANK!$G$2:$G$28,MATCH(LARGE(_RANK!$E$2:$E$28,20),_RANK!$E$2:$E$28,0)),0) -> 2473.7 | J47: =IFERROR(INDEX(_RANK!$H$2:$H$28,MATCH(LARGE(_RANK!$E$2:$E$28,20),_RANK!$E$2:$E$28,0)),0) -> 1939.33 | K47: =IFERROR(INDEX(_RANK!$I$2:$I$28,MATCH(LARGE(_RANK!$E$2:$E$28,20),_RANK!$E$2:$E$28,0)),0) -> 0.43945543 | L47: =IFERROR(INDEX(_RANK!$J$2:$J$28,MATCH(LARGE(_RANK!$E$2:$E$28,20),_RANK!$E$2:$E$28,0)),0) -> 1357.531 | M47: 🟢 BAIXO
...

Sheet _RANK
A1: UF | B1: Nome | C1: Escritura | D1: Procuracao | E1: TotalLocal | F1: Parceiro | G1: CustoParceiro | H1: Economia | I1: EconPct | J1: Bruto
A2: AC | B2: Acre | C2: =IFERROR(VLOOKUP('🏠 DASHBOARD'!$C$5,AC!$A:$C,3,TRUE()),0) -> 13440.9 | D2: 150 | E2: =C2+D2 -> 13590.9 | F2: =IF('🏠 DASHBOARD'!$C$5>515750,"DF","RS") -> RS | G2: =IF(F2="DF",IFERROR(VLOOKUP('🏠 DASHBOARD'!$C$5,DF!$A:$C,3,TRUE()),0),IFERROR(VLOOKUP('🏠 DASHBOARD'!$C$5,RS!$A:$C,3,TRUE()),0)) -> 2473.7 | H2: =MAX(E2-G2,0) -> 11117.2 | I2: =IFERROR(H2/E2,0) -> 0.81798851 | J2: =H2*'🏠 DASHBOARD'!$I$5 -> 7782.04
A3: AL | B3: Alagoas | C3: =IFERROR(VLOOKUP('🏠 DASHBOARD'!$C$5,AL!$A:$C,3,TRUE()),0) -> 11505.94 | D3: 22.43 | E3: =C3+D3 -> 11528.37 | F3: =IF('🏠 DASHBOARD'!$C$5>515750,"DF","RS") -> RS | G3: =IF(F3="DF",IFERROR(VLOOKUP('🏠 DASHBOARD'!$C$5,DF!$A:$C,3,TRUE()),0),IFERROR(VLOOKUP('🏠 DASHBOARD'!$C$5,RS!$A:$C,3,TRUE()),0)) -> 2473.7 | H3: =MAX(E3-G3,0) -> 9054.67 | I3: =IFERROR(H3/E3,0) -> 0.785425 | J3: =H3*'🏠 DASHBOARD'!$I$5 -> 6338.269
A4: AM | B4: Amazonas | C4: =IFERROR(VLOOKUP('🏠 DASHBOARD'!$C$5,AM!$A:$C,3,TRUE()),0) -> 9021.69 | D4: 200 | E4: =C4+D4 -> 9221.69 | F4: =IF('🏠 DASHBOARD'!$C$5>515750,"DF","RS") -> RS | G4: =IF(F4="DF",IFERROR(VLOOKUP('🏠 DASHBOARD'!$C$5,DF!$A:$C,3,TRUE()),0),IFERROR(VLOOKUP('🏠 DASHBOARD'!$C$5,RS!$A:$C,3,TRUE()),0)) -> 2473.7 | H4: =MAX(E4-G4,0) -> 6747.99 | I4: =IFERROR(H4/E4,0) -> 0.73175199 | J4: =H4*'🏠 DASHBOARD'!$I$5 -> 4723.593
A5: AP | B5: Amapá | C5: =IFERROR(VLOOKUP('🏠 DASHBOARD'!$C$5,AP!$A:$C,3,TRUE()),0) -> 15030.42 | D5: 200 | E5: =C5+D5 -> 15230.42 | F5: =IF('🏠 DASHBOARD'!$C$5>515750,"DF","RS") -> RS | G5: =IF(F5="DF",IFERROR(VLOOKUP('🏠 DASHBOARD'!$C$5,DF!$A:$C,3,TRUE()),0),IFERROR(VLOOKUP('🏠 DASHBOARD'!$C$5,RS!$A:$C,3,TRUE()),0)) -> 2473.7 | H5: =MAX(E5-G5,0) -> 12756.72 | I5: =IFERROR(H5/E5,0) -> 0.83758163 | J5: =H5*'🏠 DASHBOARD'!$I$5 -> 8929.704
A6: BA | B6: Bahia | C6: =IFERROR(VLOOKUP('🏠 DASHBOARD'!$C$5,BA!$A:$C,3,TRUE()),0) -> 4067.28 | D6: 118.58 | E6: =C6+D6 -> 4185.86 | F6: =IF('🏠 DASHBOARD'!$C$5>515750,"DF","RS") -> RS | G6: =IF(F6="DF",IFERROR(VLOOKUP('🏠 DASHBOARD'!$C$5,DF!$A:$C,3,TRUE()),0),IFERROR(VLOOKUP('🏠 DASHBOARD'!$C$5,RS!$A:$C,3,TRUE()),0)) -> 2473.7 | H6: =MAX(E6-G6,0) -> 1712.16 | I6: =IFERROR(H6/E6,0) -> 0.40903422 | J6: =H6*'🏠 DASHBOARD'!$I$5 -> 1198.512
A7: CE | B7: Ceará | C7: =IFERROR(VLOOKUP('🏠 DASHBOARD'!$C$5,CE!$A:$C,3,TRUE()),0) -> 3596.4 | D7: 62.13 | E7: =C7+D7 -> 3658.53 | F7: =IF('🏠 DASHBOARD'!$C$5>515750,"DF","RS") -> RS | G7: =IF(F7="DF",IFERROR(VLOOKUP('🏠 DASHBOARD'!$C$5,DF!$A:$C,3,TRUE()),0),IFERROR(VLOOKUP('🏠 DASHBOARD'!$C$5,RS!$A:$C,3,TRUE()),0)) -> 2473.7 | H7: =MAX(E7-G7,0) -> 1184.83 | I7: =IFERROR(H7/E7,0) -> 0.32385412 | J7: =H7*'🏠 DASHBOARD'!$I$5 -> 829.381
A8: DF | B8: Distrito Federal | C8: =IFERROR(VLOOKUP('🏠 DASHBOARD'!$C$5,DF!$A:$C,3,TRUE()),0) -> 2372.2 | D8: 1186.1 | E8: =C8+D8 -> 3558.3 | F8: =IF('🏠 DASHBOARD'!$C$5>515750,"DF","RS") -> RS | G8: =IF(F8="DF",IFERROR(VLOOKUP('🏠 DASHBOARD'!$C$5,DF!$A:$C,3,TRUE()),0),IFERROR(VLOOKUP('🏠 DASHBOARD'!$C$5,RS!$A:$C,3,TRUE()),0)) -> 2473.7 | H8: =MAX(E8-G8,0) -> 1084.6 | I8: =IFERROR(H8/E8,0) -> 0.30480848 | J8: =H8*'🏠 DASHBOARD'!$I$5 -> 759.22
A9: ES | B9: Espírito Santo | C9: =IFERROR(VLOOKUP('🏠 DASHBOARD'!$C$5,ES!$A:$C,3,TRUE()),0) -> 7254.52 | D9: 180 | E9: =C9+D9 -> 7434.52 | F9: =IF('🏠 DASHBOARD'!$C$5>515750,"DF","RS") -> RS | G9: =IF(F9="DF",IFERROR(VLOOKUP('🏠 DASHBOARD'!$C$5,DF!$A:$C,3,TRUE()),0),IFERROR(VLOOKUP('🏠 DASHBOARD'!$C$5,RS!$A:$C,3,TRUE()),0)) -> 2473.7 | H9: =MAX(E9-G9,0) -> 4960.82 | I9: =IFERROR(H9/E9,0) -> 0.66726836 | J9: =H9*'🏠 DASHBOARD'!$I$5 -> 3472.574
A10: GO | B10: Goiás | C10: =IFERROR(VLOOKUP('🏠 DASHBOARD'!$C$5,GO!$A:$C,3,TRUE()),0) -> 7388.58 | D10: 200 | E10: =C10+D10 -> 7588.58 | F10: =IF('🏠 DASHBOARD'!$C$5>515750,"DF","RS") -> RS | G10: =IF(F10="DF",IFERROR(VLOOKUP('🏠 DASHBOARD'!$C$5,DF!$A:$C,3,TRUE()),0),IFERROR(VLOOKUP('🏠 DASHBOARD'!$C$5,RS!$A:$C,3,TRUE()),0)) -> 2473.7 | H10: =MAX(E10-G10,0) -> 5114.88 | I10: =IFERROR(H10/E10,0) -> 0.67402334 | J10: =H10*'🏠 DASHBOARD'!$I$5 -> 3580.416
A11: MA | B11: Maranhão | C11: =IFERROR(VLOOKUP('🏠 DASHBOARD'!$C$5,MA!$A:$C,3,TRUE()),0) -> 8388.96 | D11: 200 | E11: =C11+D11 -> 8588.96 | F11: =IF('🏠 DASHBOARD'!$C$5>515750,"DF","RS") -> RS | G11: =IF(F11="DF",IFERROR(VLOOKUP('🏠 DASHBOARD'!$C$5,DF!$A:$C,3,TRUE()),0),IFERROR(VLOOKUP('🏠 DASHBOARD'!$C$5,RS!$A:$C,3,TRUE()),0)) -> 2473.7 | H11: =MAX(E11-G11,0) -> 6115.26 | I11: =IFERROR(H11/E11,0) -> 0.71199074 | J11: =H11*'🏠 DASHBOARD'!$I$5 -> 4280.682
A12: MT | B12: Mato Grosso | C12: =IFERROR(VLOOKUP('🏠 DASHBOARD'!$C$5,MT!$A:$C,3,TRUE()),0) -> 6948.45 | D12: 300 | E12: =C12+D12 -> 7248.45 | F12: =IF('🏠 DASHBOARD'!$C$5>515750,"DF","RS") -> RS | G12: =IF(F12="DF",IFERROR(VLOOKUP('🏠 DASHBOARD'!$C$5,DF!$A:$C,3,TRUE()),0),IFERROR(VLOOKUP('🏠 DASHBOARD'!$C$5,RS!$A:$C,3,TRUE()),0)) -> 2473.7 | H12: =MAX(E12-G12,0) -> 4774.75 | I12: =IFERROR(H12/E12,0) -> 0.65872704 | J12: =H12*'🏠 DASHBOARD'!$I$5 -> 3342.325
A13: MS | B13: Mato Grosso do Sul | C13: =IFERROR(VLOOKUP('🏠 DASHBOARD'!$C$5,MS!$A:$C,3,TRUE()),0) -> 8219.16 | D13: 200 | E13: =C13+D13 -> 8419.16 | F13: =IF('🏠 DASHBOARD'!$C$5>515750,"DF","RS") -> RS | G13: =IF(F13="DF",IFERROR(VLOOKUP('🏠 DASHBOARD'!$C$5,DF!$A:$C,3,TRUE()),0),IFERROR(VLOOKUP('🏠 DASHBOARD'!$C$5,RS!$A:$C,3,TRUE()),0)) -> 2473.7 | H13: =MAX(E13-G13,0) -> 5945.46 | I13: =IFERROR(H13/E13,0) -> 0.70618209 | J13: =H13*'🏠 DASHBOARD'!$I$5 -> 4161.822
A14: MG | B14: Minas Gerais | C14: =IFERROR(VLOOKUP('🏠 DASHBOARD'!$C$5,MG!$A:$C,3,TRUE()),0) -> 5523.14 | D14: 68.94 | E14: =C14+D14 -> 5592.08 | F14: =IF('🏠 DASHBOARD'!$C$5>515750,"DF","RS") -> RS | G14: =IF(F14="DF",IFERROR(VLOOKUP('🏠 DASHBOARD'!$C$5,DF!$A:$C,3,TRUE()),0),IFERROR(VLOOKUP('🏠 DASHBOARD'!$C$5,RS!$A:$C,3,TRUE()),0)) -> 2473.7 | H14: =MAX(E14-G14,0) -> 3118.38 | I14: =IFERROR(H14/E14,0) -> 0.55764224 | J14: =H14*'🏠 DASHBOARD'!$I$5 -> 2182.866
A15: PA | B15: Pará | C15: =IFERROR(VLOOKUP('🏠 DASHBOARD'!$C$5,PA!$A:$C,3,TRUE()),0) -> 4152.8 | D15: 200 | E15: =C15+D15 -> 4352.8 | F15: =IF('🏠 DASHBOARD'!$C$5>515750,"DF","RS") -> RS | G15: =IF(F15="DF",IFERROR(VLOOKUP('🏠 DASHBOARD'!$C$5,DF!$A:$C,3,TRUE()),0),IFERROR(VLOOKUP('🏠 DASHBOARD'!$C$5,RS!$A:$C,3,TRUE()),0)) -> 2473.7 | H15: =MAX(E15-G15,0) -> 1879.1 | I15: =IFERROR(H15/E15,0) -> 0.43169914 | J15: =H15*'🏠 DASHBOARD'!$I$5 -> 1315.37
A16: PB | B16: Paraíba | C16: =IFERROR(VLOOKUP('🏠 DASHBOARD'!$C$5,PB!$A:$C,3,TRUE()),0) -> 9369.12 | D16: 170.35 | E16: =C16+D16 -> 9539.47 | F16: =IF('🏠 DASHBOARD'!$C$5>515750,"DF","RS") -> RS | G16: =IF(F16="DF",IFERROR(VLOOKUP('🏠 DASHBOARD'!$C$5,DF!$A:$C,3,TRUE()),0),IFERROR(VLOOKUP('🏠 DASHBOARD'!$C$5,RS!$A:$C,3,TRUE()),0)) -> 2473.7 | H16: =MAX(E16-G16,0) -> 7065.77 | I16: =IFERROR(H16/E16,0) -> 0.7406879 | J16: =H16*'🏠 DASHBOARD'!$I$5 -> 4946.039
A17: PE | B17: Pernambuco | C17: =IFERROR(VLOOKUP('🏠 DASHBOARD'!$C$5,PE!$A:$C,3,TRUE()),0) -> 7084.1 | D17: 237.84 | E17: =C17+D17 -> 7321.94 | F17: =IF('🏠 DASHBOARD'!$C$5>515750,"DF","RS") -> RS | G17: =IF(F17="DF",IFERROR(VLOOKUP('🏠 DASHBOARD'!$C$5,DF!$A:$C,3,TRUE()),0),IFERROR(VLOOKUP('🏠 DASHBOARD'!$C$5,RS!$A:$C,3,TRUE()),0)) -> 2473.7 | H17: =MAX(E17-G17,0) -> 4848.24 | I17: =IFERROR(H17/E17,0) -> 0.66215238 | J17: =H17*'🏠 DASHBOARD'!$I$5 -> 3393.768
A18: PR | B18: Paraná | C18: =IFERROR(VLOOKUP('🏠 DASHBOARD'!$C$5,PR!$A:$C,3,TRUE()),0) -> 4460.8 | D18: 200 | E18: =C18+D18 -> 4660.8 | F18: =IF('🏠 DASHBOARD'!$C$5>515750,"DF","RS") -> RS | G18: =IF(F18="DF",IFERROR(VLOOKUP('🏠 DASHBOARD'!$C$5,DF!$A:$C,3,TRUE()),0),IFERROR(VLOOKUP('🏠 DASHBOARD'!$C$5,RS!$A:$C,3,TRUE()),0)) -> 2473.7 | H18: =MAX(E18-G18,0) -> 2187.1 | I18: =IFERROR(H18/E18,0) -> 0.46925421 | J18: =H18*'🏠 DASHBOARD'!$I$5 -> 1530.97
A19: PI | B19: Piauí | C19: =IFERROR(VLOOKUP('🏠 DASHBOARD'!$C$5,PI!$A:$C,3,TRUE()),0) -> 6360.31 | D19: 200 | E19: =C19+D19 -> 6560.31 | F19: =IF('🏠 DASHBOARD'!$C$5>515750,"DF","RS") -> RS | G19: =IF(F19="DF",IFERROR(VLOOKUP('🏠 DASHBOARD'!$C$5,DF!$A:$C,3,TRUE()),0),IFERROR(VLOOKUP('🏠 DASHBOARD'!$C$5,RS!$A:$C,3,TRUE()),0)) -> 2473.7 | H19: =MAX(E19-G19,0) -> 4086.61 | I19: =IFERROR(H19/E19,0) -> 0.6229294 | J19: =H19*'🏠 DASHBOARD'!$I$5 -> 2860.627
A20: RJ | B20: Rio de Janeiro | C20: =IFERROR(VLOOKUP('🏠 DASHBOARD'!$C$5,RJ!$A:$C,3,TRUE()),0) -> 2907.22 | D20: 435.39 | E20: =C20+D20 -> 3342.61 | F20: =IF('🏠 DASHBOARD'!$C$5>515750,"DF","RS") -> RS | G20: =IF(F20="DF",IFERROR(VLOOKUP('🏠 DASHBOARD'!$C$5,DF!$A:$C,3,TRUE()),0),IFERROR(VLOOKUP('🏠 DASHBOARD'!$C$5,RS!$A:$C,3,TRUE()),0)) -> 2473.7 | H20: =MAX(E20-G20,0) -> 868.91 | I20: =IFERROR(H20/E20,0) -> 0.25994956 | J20: =H20*'🏠 DASHBOARD'!$I$5 -> 608.237
A21: RN | B21: Rio Grande do Norte | C21: =IFERROR(VLOOKUP('🏠 DASHBOARD'!$C$5,RN!$A:$C,3,TRUE()),0) -> 14108.04 | D21: 200 | E21: =C21+D21 -> 14308.04 | F21: =IF('🏠 DASHBOARD'!$C$5>515750,"DF","RS") -> RS | G21: =IF(F21="DF",IFERROR(VLOOKUP('🏠 DASHBOARD'!$C$5,DF!$A:$C,3,TRUE()),0),IFERROR(VLOOKUP('🏠 DASHBOARD'!$C$5,RS!$A:$C,3,TRUE()),0)) -> 2473.7 | H21: =MAX(E21-G21,0) -> 11834.34 | I21: =IFERROR(H21/E21,0) -> 0.82711119 | J21: =H21*'🏠 DASHBOARD'!$I$5 -> 8284.038
A22: RS | B22: Rio Grande do Sul | C22: =IFERROR(VLOOKUP('🏠 DASHBOARD'!$C$5,RS!$A:$C,3,TRUE()),0) -> 2473.7 | D22: 110.1 | E22: =C22+D22 -> 2583.8 | F22: =IF('🏠 DASHBOARD'!$C$5>515750,"DF","RS") -> RS | G22: =IF(F22="DF",IFERROR(VLOOKUP('🏠 DASHBOARD'!$C$5,DF!$A:$C,3,TRUE()),0),IFERROR(VLOOKUP('🏠 DASHBOARD'!$C$5,RS!$A:$C,3,TRUE()),0)) -> 2473.7 | H22: =MAX(E22-G22,0) -> 110.1 | I22: =IFERROR(H22/E22,0) -> 0.042611657 | J22: =H22*'🏠 DASHBOARD'!$I$5 -> 77.07
A23: RO | B23: Rondônia | C23: =IFERROR(VLOOKUP('🏠 DASHBOARD'!$C$5,RO!$A:$C,3,TRUE()),0) -> 8711.83 | D23: 200 | E23: =C23+D23 -> 8911.83 | F23: =IF('🏠 DASHBOARD'!$C$5>515750,"DF","RS") -> RS | G23: =IF(F23="DF",IFERROR(VLOOKUP('🏠 DASHBOARD'!$C$5,DF!$A:$C,3,TRUE()),0),IFERROR(VLOOKUP('🏠 DASHBOARD'!$C$5,RS!$A:$C,3,TRUE()),0)) -> 2473.7 | H23: =MAX(E23-G23,0) -> 6438.13 | I23: =IFERROR(H23/E23,0) -> 0.72242514 | J23: =H23*'🏠 DASHBOARD'!$I$5 -> 4506.691
A24: RR | B24: Roraima | C24: =IFERROR(VLOOKUP('🏠 DASHBOARD'!$C$5,RR!$A:$C,3,TRUE()),0) -> 4213.03 | D24: 200 | E24: =C24+D24 -> 4413.03 | F24: =IF('🏠 DASHBOARD'!$C$5>515750,"DF","RS") -> RS | G24: =IF(F24="DF",IFERROR(VLOOKUP('🏠 DASHBOARD'!$C$5,DF!$A:$C,3,TRUE()),0),IFERROR(VLOOKUP('🏠 DASHBOARD'!$C$5,RS!$A:$C,3,TRUE()),0)) -> 2473.7 | H24: =MAX(E24-G24,0) -> 1939.33 | I24: =IFERROR(H24/E24,0) -> 0.43945543 | J24: =H24*'🏠 DASHBOARD'!$I$5 -> 1357.531
A25: SC | B25: Santa Catarina | C25: =IFERROR(VLOOKUP('🏠 DASHBOARD'!$C$5,SC!$A:$C,3,TRUE()),0) -> 2997.58 | D25: 62.59 | E25: =C25+D25 -> 3060.17 | F25: =IF('🏠 DASHBOARD'!$C$5>515750,"DF","RS") -> RS | G25: =IF(F25="DF",IFERROR(VLOOKUP('🏠 DASHBOARD'!$C$5,DF!$A:$C,3,TRUE()),0),IFERROR(VLOOKUP('🏠 DASHBOARD'!$C$5,RS!$A:$C,3,TRUE()),0)) -> 2473.7 | H25: =MAX(E25-G25,0) -> 586.47 | I25: =IFERROR(H25/E25,0) -> 0.19164622 | J25: =H25*'🏠 DASHBOARD'!$I$5 -> 410.529
A26: SE | B26: Sergipe | C26: =IFERROR(VLOOKUP('🏠 DASHBOARD'!$C$5,SE!$A:$C,3,TRUE()),0) -> 5179.16 | D26: 200 | E26: =C26+D26 -> 5379.16 | F26: =IF('🏠 DASHBOARD'!$C$5>515750,"DF","RS") -> RS | G26: =IF(F26="DF",IFERROR(VLOOKUP('🏠 DASHBOARD'!$C$5,DF!$A:$C,3,TRUE()),0),IFERROR(VLOOKUP('🏠 DASHBOARD'!$C$5,RS!$A:$C,3,TRUE()),0)) -> 2473.7 | H26: =MAX(E26-G26,0) -> 2905.46 | I26: =IFERROR(H26/E26,0) -> 0.54013266 | J26: =H26*'🏠 DASHBOARD'!$I$5 -> 2033.822
A27: SP | B27: São Paulo | C27: =IFERROR(VLOOKUP('🏠 DASHBOARD'!$C$5,SP!$A:$C,3,TRUE()),0) -> 6942.82 | D27: 200 | E27: =C27+D27 -> 7142.82 | F27: =IF('🏠 DASHBOARD'!$C$5>515750,"DF","RS") -> RS | G27: =IF(F27="DF",IFERROR(VLOOKUP('🏠 DASHBOARD'!$C$5,DF!$A:$C,3,TRUE()),0),IFERROR(VLOOKUP('🏠 DASHBOARD'!$C$5,RS!$A:$C,3,TRUE()),0)) -> 2473.7 | H27: =MAX(E27-G27,0) -> 4669.12 | I27: =IFERROR(H27/E27,0) -> 0.6536802 | J27: =H27*'🏠 DASHBOARD'!$I$5 -> 3268.384
A28: TO | B28: Tocantins | C28: =IFERROR(VLOOKUP('🏠 DASHBOARD'!$C$5,TO!$A:$C,3,TRUE()),0) -> 5075.36 | D28: 200 | E28: =C28+D28 -> 5275.36 | F28: =IF('🏠 DASHBOARD'!$C$5>515750,"DF","RS") -> RS | G28: =IF(F28="DF",IFERROR(VLOOKUP('🏠 DASHBOARD'!$C$5,DF!$A:$C,3,TRUE()),0),IFERROR(VLOOKUP('🏠 DASHBOARD'!$C$5,RS!$A:$C,3,TRUE()),0)) -> 2473.7 | H28: =MAX(E28-G28,0) -> 2801.66 | I28: =IFERROR(H28/E28,0) -> 0.53108413 | J28: =H28*'🏠 DASHBOARD'!$I$5 -> 1961.162

Sheet _LISTAS
A1: AC | B1: AC — Acre | C1: 13440.9 | D1: 150
A2: AL | B2: AL — Alagoas | C2: 11505.94 | D2: 22.43
A3: AM | B3: AM — Amazonas | C3: 9021.69 | D3: 200
A4: AP | B4: AP — Amapá | C4: 15030.42 | D4: 200
A5: BA | B5: BA — Bahia | C5: 4067.28 | D5: 118.58
A6: CE | B6: CE — Ceará | C6: 3596.4 | D6: 62.13
A7: DF | B7: DF — Distrito Federal | C7: 2372.2 | D7: 1186.1
A8: ES | B8: ES — Espírito Santo | C8: 7254.52 | D8: 180
A9: GO | B9: GO — Goiás | C9: 7388.58 | D9: 200
A10: MA | B10: MA — Maranhão | C10: 8388.96 | D10: 200
A11: MT | B11: MT — Mato Grosso | C11: 6948.45 | D11: 300
A12: MS | B12: MS — Mato Grosso do Sul | C12: 8219.16 | D12: 200
... A27: TO | B27: TO — Tocantins | C27: 5075.36 | D27: 200

Sheet AC
A1: AC — Acre
A2: Fonte: | B2: TJAC 2025
A3: ⚠️ Verificar tabela completa no TJAC
A5: De (R$) | B5: Até (R$) | C5: Emolumento (R$)
A6: 0 | B6: 3000 | C6: 139.7
A7: 3000.01 | B7: 5000 | C7: 403.2
A8: 5000.01 | B8: 15000 | C8: 537.6
A9: 15000.01 | B9: 30000 | C9: 806.6
A10: 30000.01 | B10: 50000 | C10: 1344.2
A11: 50000.01 | B11: 80000 | C11: 2150.5
A12: 80000.01 | B12: 100000 | C12: 2688.1
A13: 100000.01 | B13: 150000 | C13: 4032.4
A14: 150000.01 | B14: 200000 | C14: 5376.4
A15: 200000.01 | B15: 250000 | C15: 6720.8
A16: 250000.01 | B16: 300000 | C16: 8064.7
A17: 300000.01 | B17: 350000 | C17: 9408.8
... A20: 500000.01 | B20: 999999999 | C20: 16129.3

Sheet AL
A1: AL — Alagoas
A2: Fonte: | B2: TJAL — Tabela vigente 2025
A3: ✅ CORRIGIDO — Fórmula progressiva (+R$28,66/R$1.280) teto R$175.392,87. Procuração R$22,43
A5: De (R$) | B5: Até (R$) | C5: Emolumento (R$)
A6: 0 | B6: 6.4 | C6: 14.32
A7: 6.41 | B7: 12.8 | C7: 21.44
A8: 12.81 | B8: 38.4 | C8: 35.75
A9: 38.41 | B9: 96 | C9: 49.89
A10: 96.01 | B10: 160 | C10: 64.08
A11: 160.01 | B11: 480 | C11: 107.19
A12: 480.01 | B12: 960 | C12: 142.89
A13: 960.01 | B13: 1920 | C13: 214.35
A14: 1920.01 | B14: 2560 | C14: 285.76
A15: 2560.01 | B15: 3200 | C15: 357.2
A16: 3200.01 | B16: 4480 | C16: 385.86
A17: 4480.01 | B17: 5760 | C17: 414.52
... A6123: 7820160 | B6123: 999999999 | C6123: 175392.87

Sheet AM
A1: AM — Amazonas
A2: Fonte: | B2: TJAM 2025
A4: De (R$) | B4: Até (R$) | C4: Emolumento (R$)
A5: 0.01 | B5: 17595 | C5: 516.06
A6: 17595.01 | B6: 35190 | C6: 858.23
A7: 35190.01 | B7: 58650 | C7: 1094.42
A8: 58650.01 | B8: 117300 | C8: 1473.45
A9: 117300.01 | B9: 234600 | C9: 2664.93
A10: 234600.01 | B10: 351900 | C10: 4482.42
A11: 351900.01 | B11: 469200 | C11: 7053.31
A12: 469200.01 | B12: 586500 | C12: 9021.69
A13: 586500.01 | B13: 703800 | C13: 11094.93
A14: 703800.01 | B14: 821100 | C14: 11447.13
A15: 821100.01 | B15: 938400 | C15: 12864.35
A16: 938400.01 | B16: 999999999 | C16: 17509.72

Sheet AP
A1: AP — Amapá
A2: Fonte: | B2: TJAP 2025
A4: De (R$) | B4: Até (R$) | C4: Emolumento (R$)
A5: 0 | B5: 3000 | C5: 240.5
A6: 3000.01 | B6: 5000 | C6: 450.88
A7: 5000.01 | B7: 15000 | C7: 601.22
A8: 15000.01 | B8: 30000 | C8: 901.82
A9: 30000.01 | B9: 50000 | C9: 1503.02
A10: 50000.01 | B10: 80000 | C10: 2405.36
A11: 80000.01 | B11: 100000 | C11: 3006.08
A12: 100000.01 | B12: 150000 | C12: 4509.1
A13: 150000.01 | B13: 200000 | C13: 6012.15
A14: 200000.01 | B14: 250000 | C14: 7515.17
A15: 250000.01 | B15: 300000 | C15: 9018.23
A16: 300000.01 | B16: 350000 | C16: 10521.28
... A20: 1000000 | B20: 999999999 | C20: 24048.71

Sheet BA
A1: BA — Bahia
A2: Fonte: | B2: TJBA — Decreto 954/2024
A3: ✅ VERIFICADO — Fonte oficial TJBA + Procuração R$118,58 (confirmada PDF)
A5: De (R$) | B5: Até (R$) | C5: Emolumento (R$)
A6: 0 | B6: 1600 | C6: 319.12
A7: 1600.01 | B7: 3200 | C7: 401.4
A8: 3200.01 | B8: 8000 | C8: 483.68
A9: 8000.01 | B9: 12000 | C9: 522.76
A10: 12000.01 | B10: 16000 | C10: 562.54
A11: 16000.01 | B11: 24000 | C11: 642.22
A12: 24000.01 | B12: 32000 | C12: 723.98
A13: 32000.01 | B13: 47000 | C13: 799.68
A14: 47000.01 | B14: 63000 | C14: 881.24
A15: 63000.01 | B15: 78000 | C15: 967.68
A16: 78000.01 | B16: 118000 | C16: 1030.66
A17: 118000.01 | B17: 160000 | C17: 1115.1
... A24: 1800000 | B24: 999999999 | C24: 18551.68

Sheet CE
A1: CE — Ceará
A2: Fonte: | B2: TJCE — Portaria 2749/2024-GABPRESI (vigência 01/01/2025)
A3: ✅ CORRIGIDO — Tabela FORA DO MUNICÍPIO (002022-002031). Teto R$3.088,94 → total máx R$3.596,40
A5: De (R$) | B5: Até (R$) | C5: Emolumento (R$)
A6: 0 | B6: 104 | C6: 143.98
A7: 104.01 | B7: 235 | C7: 344.11
A8: 235.01 | B8: 784 | C8: 429.1
A9: 784.01 | B9: 2376 | C9: 465.89
A10: 2376.01 | B10: 4684 | C10: 597.11
A11: 4684.01 | B11: 6540 | C11: 641.45
A12: 6540.01 | B12: 9810 | C12: 729.29
A13: 9810.01 | B13: 18527 | C13: 860.5
A14: 18527.01 | B14: 23322.58 | C14: 964.3
A15: 23322.59 | B15: 23522.58 | C15: 969.33
A16: 23522.59 | B16: 23722.58 | C16: 974.08
A17: 23722.59 | B17: 23922.58 | C17: 978.84
... A561: 132522.59 | B561: 999999999 | C561: 3596.4

Sheet DF
A1: DF — Distrito Federal
A2: Fonte: | B2: ANOREG/DF — Resolução 2/2025
A3: ✅ VERIFICADO — Tabela 2026 vigente + Procuração = 50% escritura (R$1.186,10 para R$500k)
A5: De (R$) | B5: Até (R$) | C5: Emolumento (R$)
A6: 0 | B6: 9524.89 | C6: 439.29
A7: 9524.9 | B7: 15272.67 | C7: 667.73
A8: 15272.68 | B8: 28738.89 | C8: 1370.6
A9: 28738.9 | B9: 57477.78 | C9: 1845.05
A10: 57477.79 | B10: 85888.21 | C10: 1932.9
A11: 85888.22 | B11: 200351.09 | C11: 2020.76
A12: 200351.1 | B12: 343224.42 | C12: 2196.48
A13: 343224.43 | B13: 858882.16 | C13: 2372.2
A14: 858882.17 | B14: 1313777.7 | C14: 2547.91
A15: 1313777.7 | B15: 1806444.3 | C15: 2723.63
A16: 1806444.3 | B16: 999999999 | C16: 2899.35

Sheet ES
A1: ES — Espírito Santo
A2: Fonte: | B2: TJES 2025
A4: De (R$) | B4: Até (R$) | C4: Emolumento (R$)
A5: 0 | B5: 2500 | C5: 136.87
A6: 2500.01 | B6: 5000 | C6: 196.76
A7: 5000.01 | B7: 10000 | C7: 325.09
A8: 10000.01 | B8: 15000 | C8: 496.19
A9: 15000.01 | B9: 20000 | C9: 667.29
A10: 20000.01 | B10: 25000 | C10: 838.38
A11: 25000.01 | B11: 30000 | C11: 1009.48
A12: 30000.01 | B12: 40000 | C12: 1351.69
A13: 40000.01 | B13: 50000 | C13: 1693.87
A14: 50000.01 | B14: 60000 | C14: 2036.07
A15: 60000.01 | B15: 70000 | C15: 2378.26
A16: 70000.01 | B16: 80000 | C16: 2720.46
... A24: 200000.01 | B24: 999999999 | C24: 7254.52

Sheet GO
A1: GO — Goiás
A2: Fonte: | B2: TJGO 2026
A4: De (R$) | B4: Até (R$) | C4: Emolumento (R$)
A5: 0 | B5: 653.8 | C5: 253.93
A6: 653.81 | B6: 1307.62 | C6: 326.18
A7: 1307.63 | B7: 2615.24 | C7: 399.92
A8: 2615.25 | B8: 5230.47 | C8: 513.9
A9: 5230.48 | B9: 10460.94 | C9: 910.72
A10: 10460.95 | B10: 15691.43 | C10: 966.38
A11: 15691.44 | B11: 26152.37 | C11: 1193.71
A12: 26152.38 | B12: 39228.54 | C12: 1478.98
A13: 39228.55 | B13: 52304.74 | C13: 1905.98
A14: 52304.75 | B14: 65380.92 | C14: 2276.96
A15: 65380.93 | B15: 104609.47 | C15: 2956.62
A16: 104609.48 | B16: 156914.21 | C16: 4176.22
... A23: 575478.23 | B23: 999999999 | C23: 8211.51

Sheet MA
A1: MA — Maranhão
A2: Fonte: | B2: TJMA 2025
A4: De (R$) | B4: Até (R$) | C4: Emolumento (R$)
A5: 0 | B5: 7396.72 | C5: 167.52
A6: 7396.73 | B6: 11538.86 | C6: 209.47
A7: 11538.87 | B7: 14423.58 | C7: 236.81
A8: 14423.59 | B8: 18029.47 | C8: 296.05
A9: 18029.48 | B9: 22536.85 | C9: 368.36
A10: 22536.86 | B10: 28171.04 | C10: 459.97
A11: 28171.05 | B11: 35213.8 | C11: 575.45
A12: 35213.81 | B12: 44017.25 | C12: 720.99
A13: 44017.26 | B13: 55021.55 | C13: 901.39
A14: 55021.56 | B14: 68776.92 | C14: 1124.85
A15: 68776.93 | B15: 85971.18 | C15: 1407.25
A16: 85971.19 | B16: 107463.97 | C16: 1759.88
... A24: 512428.13 | B24: 999999999 | C24: 17299.63

Sheet MT
A1: MT — Mato Grosso
A2: Fonte: | B2: TJMT — Provimento 80/2025 (2026)
A3: ✅ CORRIGIDO — Tabela 2026 (reajuste 15,30%). Máximo R$6.948,45 confirmado
A5: De (R$) | B5: Até (R$) | C5: Emolumento (R$)
A6: 0 | B6: 5353.45 | C6: 300.65
A7: 5353.46 | B7: 999999999 | C7: 6948.45

Sheet MS
A1: MS — Mato Grosso do Sul
A2: Fonte: | B2: TJMS 2025
A4: De (R$) | B4: Até (R$) | C4: Emolumento (R$)
A5: 0.01 | B5: 5000 | C5: 213.16
A6: 5000.01 | B6: 10000 | C6: 312.14
A7: 10000.01 | B7: 15000 | C7: 457.96
A8: 15000.01 | B8: 20000 | C8: 614.63
A9: 20000.01 | B9: 25000 | C9: 771.3
A10: 25000.01 | B10: 30000 | C10: 915.92
A11: 30000.01 | B11: 35000 | C11: 1078.61
A12: 35000.01 | B12: 40000 | C12: 1229.26
A13: 40000.01 | B13: 50000 | C13: 1542.6
A14: 50000.01 | B14: 60000 | C14: 1831.84
A15: 60000.01 | B15: 70000 | C15: 2157.23
A16: 70000.01 | B16: 80000 | C16: 2458.52
... A28: 1000000 | B28: 999999999 | C28: 9641.25

Sheet MG
A1: MG — Minas Gerais
A2: Fonte: | B2: TJMG 2025
A3: ✅ Procuração R$68,94 confirmada (genérica por outorgante)
A5: De (R$) | B5: Até (R$) | C5: Emolumento (R$)
A6: 0 | B6: 1400 | C6: 220.55
A7: 1400.01 | B7: 2720 | C7: 359.76
A8: 2720.01 | B8: 5440 | C8: 521.35
A9: 5440.01 | B9: 7000 | C9: 721.75
A10: 7000.01 | B10: 14000 | C10: 962.47
A11: 14000.01 | B11: 28000 | C11: 1243.47
A12: 28000.01 | B12: 42000 | C12: 1564.07
A13: 42000.01 | B13: 56000 | C13: 1925.31
A14: 56000.01 | B14: 70000 | C14: 2326.51
A15: 70000.01 | B15: 105000 | C15: 2928.06
A16: 105000.01 | B16: 140000 | C16: 3721.52
A17: 140000.01 | B17: 175000 | C17: 3979.69
... A24: 700000.01 | B24: 999999999 | C24: 8582.97

Sheet PA
A1: PA — Pará
A2: Fonte: | B2: TJPA 2025
A4: De (R$) | B4: Até (R$) | C4: Emolumento (R$)
A5: 0 | B5: 15000 | C5: 441.4
A6: 15000.01 | B6: 30000 | C6: 540
A7: 30000.01 | B7: 45000 | C7: 835.7
A8: 45000.01 | B8: 60000 | C8: 1090.2
A9: 60000.01 | B9: 75000 | C9: 1344.8
A10: 75000.01 | B10: 90000 | C10: 1599.3
A11: 90000.01 | B11: 120000 | C11: 2036.1
A12: 120000.01 | B12: 150000 | C12: 2472.9
A13: 150000.01 | B13: 210000 | C13: 2542.6
A14: 210000.01 | B14: 270000 | C14: 2844.5
A15: 270000.01 | B15: 390000 | C15: 3458.6
A16: 390000.01 | B16: 510000 | C16: 4152.8
... A19: 1110000 | B19: 999999999 | C19: 8602.4

Sheet PB
A1: PB — Paraíba
A2: Fonte: | B2: ANOREG/PB — Ato CGJ 01/2025 (2026)
A3: ✅ CORRIGIDO — Faixas progressivas confirmadas. Procuração R$170,35 (confirmada PDF)
A5: De (R$) | B5: Até (R$) | C5: Emolumento (R$)
A6: 0 | B6: 17745 | C6: 298.12
A7: 17745.01 | B7: 35490 | C7: 745.29
A8: 35490.01 | B8: 49686 | C8: 1192.46
A9: 49686.01 | B9: 56784 | C9: 1320.22
A10: 56784.01 | B10: 63882 | C10: 1448
A11: 63882.01 | B11: 70980 | C11: 1575.76
A12: 70980.01 | B12: 78078 | C12: 1703.52
A13: 78078.01 | B13: 85176 | C13: 1831.28
A14: 85176.01 | B14: 92274 | C14: 1959.04
A15: 92274.01 | B15: 99372 | C15: 2086.8
A16: 99372.01 | B16: 106470 | C16: 2214.56
A17: 106470.01 | B17: 113568 | C17: 2342.32
... A74: 511056.01 | B74: 999999999 | C74: 21294

Sheet PE
A1: PE — Pernambuco
A2: Fonte: | B2: TJPE 2025
A3: ✅ Procuração R$237,84 confirmada (em causa própria/alienação bens)
A5: De (R$) | B5: Até (R$) | C5: Emolumento (R$)
A6: 0 | B6: 1000 | C6: 237.84
A7: 1000.01 | B7: 5000 | C7: 399.5
A8: 5000.01 | B8: 10000 | C8: 561.13
A9: 10000.01 | B9: 15000 | C9: 722.8
A10: 15000.01 | B10: 25000 | C10: 965.28
A11: 25000.01 | B11: 50000 | C11: 1773.53
A12: 50000.01 | B12: 100000 | C12: 3390.06
A13: 100000.01 | B13: 150000 | C13: 5006.54
A14: 150000.01 | B14: 200000 | C14: 6623.08
A15: 200000.01 | B15: 210000 | C15: 6946.38
A16: 210000.01 | B16: 999999999 | C16: 7084.1

Sheet PR
A1: PR — Paraná
A2: Fonte: | B2: TJPR 2025
A3: ⚠️ Tabela incompleta acima de R$226k — verificar TJPR
A5: De (R$) | B5: Até (R$) | C5: Emolumento (R$)
A6: 0 | B6: 56000 | C6: 698.04
A7: 56000.01 | B7: 66000 | C7: 822.68
A8: 66000.01 | B8: 76000 | C8: 947.34
A9: 76000.01 | B9: 86000 | C9: 1072
A10: 86000.01 | B10: 96000 | C10: 1196.64
A11: 96000.01 | B11: 106000 | C11: 1321.29
A12: 106000.01 | B12: 116000 | C12: 1445.94
A13: 116000.01 | B13: 126000 | C13: 1570.58
A14: 126000.01 | B14: 136000 | C14: 1695.24
A15: 136000.01 | B15: 146000 | C15: 1819.88
A16: 146000.01 | B16: 156000 | C16: 1944.54
A17: 156000.01 | B17: 166000 | C17: 2024.2
... A24: 226000.01 | B24: 999999999 | C24: 4460.8

Sheet PI
A1: PI — Piauí
A2: Fonte: | B2: TJPI — Tabela vigente 2025/2026
A3: ✅ CORRIGIDO — Tabela código 34 (Escritura com valor). R$500k = R$6,360.31
A5: De (R$) | B5: Até (R$) | C5: Emolumento (R$)
A6: 0.01 | B6: 1424.36 | C6: 370.39
A7: 1424.37 | B7: 2848.72 | C7: 411.53
A8: 2848.73 | B8: 4171.34 | C8: 466.43
A9: 4171.35 | B9: 5595.7 | C9: 521.31
A10: 5595.71 | B10: 7020.06 | C10: 576.2
A11: 7020.07 | B11: 12514.02 | C11: 644.84
A12: 12514.03 | B12: 18109.72 | C12: 713.43
A13: 18109.73 | B13: 27775.02 | C13: 782.08
A14: 27775.03 | B14: 55550.04 | C14: 960.5
A15: 55550.05 | B15: 61044 | C15: 1143.96
A16: 61044.01 | B16: 71218 | C16: 1258.35
A17: 71218.01 | B17: 81392 | C17: 1384.19
... A50: 50870000 | B50: 999999999 | C50: 32148.01

Sheet RJ
A1: RJ — Rio de Janeiro
A2: Fonte: | B2: PJERJ/CGJ — Tabela 07 (Tabela 22 - Lei 9.873/22) vigência 2026
A3: ✅ CORRIGIDO — Nota 19ª: +R$252,43 a cada R$140.427,98 acima de R$561.712. R$500k=R$2,907.22
A5: De (R$) | B5: Até (R$) | C5: Emolumento (R$)
A6: 0 | B6: 21064.17 | C6: 338.53
A7: 21064.18 | B7: 42128.37 | C7: 559.41
A8: 42128.38 | B8: 63192.57 | C8: 780.34
A9: 63192.58 | B9: 84256.79 | C9: 957.01
A10: 84256.8 | B10: 112342.37 | C10: 1696.29
A11: 112342.38 | B11: 140427.98 | C11: 2002.57
A12: 140427.99 | B12: 280855.98 | C12: 2709.37
A13: 280855.99 | B13: 561711.99 | C13: 2907.22
A14: 561712 | B14: 702139.97 | C14: 3159.65
A15: 702139.98 | B15: 842567.95 | C15: 3412.08
A16: 842567.96 | B16: 982995.93 | C16: 3664.51
A17: 982995.94 | B17: 1123423.9 | C17: 3916.94
... A722: 99984722 | B722: 999999999 | C722: 182132.52

Sheet RN
A1: RN — Rio Grande do Norte
A2: Fonte: | B2: TJRN 2025
A4: De (R$) | B4: Até (R$) | C4: Emolumento (R$)
A5: 0 | B5: 10000 | C5: 339.69
A6: 10000.01 | B6: 20000 | C6: 450.28
A7: 20000.01 | B7: 30000 | C7: 679.24
A8: 30000.01 | B8: 50000 | C8: 1350.74
A9: 50000.01 | B9: 80000 | C9: 2245.36
A10: 80000.01 | B10: 100000 | C10: 2843.74
A11: 100000.01 | B11: 150000 | C11: 3751.93
A12: 150000.01 | B12: 200000 | C12: 5244.94
A13: 200000.01 | B13: 300000 | C13: 8205.01
A14: 300000.01 | B14: 400000 | C14: 11155.01
A15: 400000.01 | B15: 500000 | C15: 14108.04
A16: 500000.01 | B16: 999999999 | C16: 15495.85

Sheet RS
A1: RS — Rio Grande do Sul
A2: Fonte: | B2: TJRS/ARPEN-RS — DJe 8048/2025 (2026)
A3: ✅ CORRIGIDO — Tabela 2026 (reajuste 5,86% IPC/IEPE/UFRGS). Procuração R$110,10 confirmada
A5: De (R$) | B5: Até (R$) | C5: Emolumento (R$)
A6: 0 | B6: 2481.8 | C6: 222.8
A7: 2481.81 | B7: 7445.2 | C7: 252.5
A8: 7445.21 | B8: 12408.7 | C8: 292.4
A9: 12408.71 | B9: 18612.9 | C9: 346.1
A10: 18612.91 | B10: 24816.8 | C10: 395.6
A11: 24816.81 | B11: 37225.2 | C11: 468.1
A12: 37225.21 | B12: 49633.8 | C12: 552.7
A13: 49633.81 | B13: 74451 | C13: 628.7
A14: 74451.01 | B14: 99267.8 | C14: 728.6
A15: 99267.81 | B15: 124085 | C15: 828.5
A16: 124085.01 | B16: 148901.6 | C16: 928.1
A17: 148901.61 | B17: 198535.7 | C17: 1076.7
... A31: 1240847.6 | B31: 999999999 | C31: 5482.9

Sheet RO
A1: RO — Rondônia
A2: Fonte: | B2: TJRO 2025
A4: De (R$) | B4: Até (R$) | C4: Emolumento (R$)
A5: 0.01 | B5: 29684 | C5: 424.37
A6: 29684.01 | B6: 39386 | C6: 819.07
A7: 39386.01 | B7: 49085 | C7: 1016.35
A8: 49085.01 | B8: 68487 | C8: 1411.06
A9: 68487.01 | B9: 97591 | C9: 2002.95
A10: 97591.01 | B10: 136393 | C10: 2679.49
A11: 136393.01 | B11: 175198 | C11: 3271.44
A12: 175198.01 | B12: 252804 | C12: 4483.57
A13: 252804.01 | B13: 330410 | C13: 5554.73
A14: 330410.01 | B14: 466223 | C14: 7415.17
A15: 466223.01 | B15: 563231 | C15: 8711.83
A16: 563231.01 | B16: 999999999 | C16: 9923.96

Sheet RR
A1: RR — Roraima
A2: Fonte: | B2: TJRR 2025
A4: De (R$) | B4: Até (R$) | C4: Emolumento (R$)
A5: 0 | B5: 5000 | C5: 146.87
A6: 5000.01 | B6: 10000 | C6: 197.63
A7: 10000.01 | B7: 15000 | C7: 265.75
A8: 15000.01 | B8: 20000 | C8: 358.55
A9: 20000.01 | B9: 25000 | C9: 483.23
A10: 25000.01 | B10: 30000 | C10: 651.39
A11: 30000.01 | B11: 35000 | C11: 877.56
A12: 35000.01 | B12: 50000 | C12: 1184.91
A13: 50000.01 | B13: 100000 | C13: 1599.55
A14: 100000.01 | B14: 200000 | C14: 2159.16
A15: 200000.01 | B15: 300000 | C15: 2913.03
A16: 300000.01 | B16: 999999999 | C16: 4213.03

Sheet SC
A1: SC — Santa Catarina
A2: Fonte: | B2: TJSC — Circular CGJ 643/2025 (2026)
A3: ✅ CORRIGIDO — Tabela 2026. Fórmula acima R$226k (+R$50/R$50k). Procuração R$62,59 confirmada
A5: De (R$) | B5: Até (R$) | C5: Emolumento (R$)
A6: 0.01 | B6: 13786.58 | C6: 209.8
A7: 13786.59 | B7: 20679.87 | C7: 241.93
A8: 20679.88 | B8: 28951.83 | C8: 343.47
A9: 28951.84 | B9: 35845.12 | C9: 448.36
A10: 35845.13 | B10: 44117.08 | C10: 560.04
A11: 44117.09 | B11: 53767.69 | C11: 675.11
A12: 53767.7 | B12: 62039.64 | C12: 795.24
A13: 62039.65 | B13: 71690.25 | C13: 918.74
A14: 71690.26 | B14: 79962.21 | C14: 1047.35
A15: 79962.22 | B15: 90991.48 | C15: 1181.03
A16: 90991.49 | B16: 100642.09 | C16: 1321.48
A17: 100642.1 | B17: 111671.36 | C17: 1465.27
... A33: 526100.06 | B33: 999999999 | C33: 2997.58

Sheet SE
A1: SE — Sergipe
A2: Fonte: | B2: TJSE 2025
A4: De (R$) | B4: Até (R$) | C4: Emolumento (R$)
A5: 0 | B5: 5999.99 | C5: 303.09
A6: 6000 | B6: 12999.99 | C6: 513.01
A7: 13000 | B7: 25000 | C7: 708.46
A8: 25000.01 | B8: 50000 | C8: 943.76
A9: 50000.01 | B9: 100000 | C9: 1414.36
A10: 100000.01 | B10: 150000 | C10: 1884.96
A11: 150000.01 | B11: 200000 | C11: 2355.56
A12: 200000.01 | B12: 300000 | C12: 3296.76
A13: 300000.01 | B13: 500000 | C13: 5179.16
A14: 500000.01 | B14: 999999999 | C14: 10696.68

Sheet SP
A1: SP — São Paulo
A2: Fonte: | B2: CNB/SP 2026
A4: De (R$) | B4: Até (R$) | C4: Emolumento (R$)
A5: 0 | B5: 1024.55 | C5: 262.6
A6: 1024.56 | B6: 5707.56 | C6: 539.9
A7: 5707.57 | B7: 9530.3 | C7: 822.17
A8: 9530.31 | B8: 14213.2 | C8: 1174.83
A9: 14213.21 | B9: 19423.55 | C9: 1537.61
A10: 19423.56 | B10: 38833.65 | C10: 1883.31
A11: 38833.66 | B11: 78583.05 | C11: 2338.49
A12: 78583.06 | B12: 118332.6 | C12: 2849.74
A13: 118332.61 | B13: 162190 | C13: 3310.03
A14: 162190.01 | B14: 228319.2 | C14: 3935.14
A15: 228319.21 | B15: 307853.2 | C15: 4526.22
A16: 307853.21 | B16: 384220.1 | C16: 5457.74
... A19: 772332.06 | B19: 999999999 | C19: 13152.36

Sheet TO
A1: TO — Tocantins
A2: Fonte: | B2: TJTO 2025
A3: ⚠️ Tabela incompleta — verificar TJTO
A5: De (R$) | B5: Até (R$) | C5: Emolumento (R$)
A6: 0 | B6: 3000 | C6: 247.97
A7: 3000.01 | B7: 6000 | C7: 498.73
A8: 6000.01 | B8: 10000 | C8: 839.32
A9: 10000.01 | B9: 20000 | C9: 1224.05
A10: 20000.01 | B10: 30000 | C10: 1979.26
A11: 30000.01 | B11: 40000 | C11: 2592
A12: 40000.01 | B12: 60000 | C12: 3119.25
A13: 60000.01 | B13: 80000 | C13: 3409.94
A14: 80000.01 | B14: 999999999 | C14: 5075.36
